[2024-02-22T19:47:57.513+0000] {taskinstance.py:1956} INFO - Dependencies all met for dep_context=non-requeueable deps ti=<TaskInstance: api_dag.transform_load_data_task manual__2024-02-22T19:47:51.878932+00:00 [queued]>
[2024-02-22T19:47:57.522+0000] {taskinstance.py:1956} INFO - Dependencies all met for dep_context=requeueable deps ti=<TaskInstance: api_dag.transform_load_data_task manual__2024-02-22T19:47:51.878932+00:00 [queued]>
[2024-02-22T19:47:57.523+0000] {taskinstance.py:2170} INFO - Starting attempt 1 of 1
[2024-02-22T19:47:57.536+0000] {taskinstance.py:2191} INFO - Executing <Task(PythonOperator): transform_load_data_task> on 2024-02-22 19:47:51.878932+00:00
[2024-02-22T19:47:57.544+0000] {standard_task_runner.py:60} INFO - Started process 2748 to run task
[2024-02-22T19:47:57.547+0000] {standard_task_runner.py:87} INFO - Running: ['***', 'tasks', 'run', 'api_dag', 'transform_load_data_task', 'manual__2024-02-22T19:47:51.878932+00:00', '--job-id', '342', '--raw', '--subdir', 'DAGS_FOLDER/api_dag.py', '--cfg-path', '/tmp/tmpnivyi621']
[2024-02-22T19:47:57.548+0000] {standard_task_runner.py:88} INFO - Job 342: Subtask transform_load_data_task
[2024-02-22T19:47:57.595+0000] {task_command.py:423} INFO - Running <TaskInstance: api_dag.transform_load_data_task manual__2024-02-22T19:47:51.878932+00:00 [running]> on host 614a08523528
[2024-02-22T19:47:57.668+0000] {taskinstance.py:2480} INFO - Exporting env vars: AIRFLOW_CTX_DAG_OWNER='***' AIRFLOW_CTX_DAG_ID='api_dag' AIRFLOW_CTX_TASK_ID='transform_load_data_task' AIRFLOW_CTX_EXECUTION_DATE='2024-02-22T19:47:51.878932+00:00' AIRFLOW_CTX_TRY_NUMBER='1' AIRFLOW_CTX_DAG_RUN_ID='manual__2024-02-22T19:47:51.878932+00:00'
[2024-02-22T19:47:57.717+0000] {taskinstance.py:2698} ERROR - Task failed with exception
Traceback (most recent call last):
  File "/home/airflow/.local/lib/python3.8/site-packages/airflow/models/taskinstance.py", line 433, in _execute_task
    result = execute_callable(context=context, **execute_callable_kwargs)
  File "/home/airflow/.local/lib/python3.8/site-packages/airflow/operators/python.py", line 199, in execute
    return_value = self.execute_callable()
  File "/home/airflow/.local/lib/python3.8/site-packages/airflow/operators/python.py", line 216, in execute_callable
    return self.python_callable(*self.op_args, **self.op_kwargs)
  File "/opt/airflow/dags/api_dag.py", line 28, in transform_data
    normalized_csv_data = [{'idMezzo': item['Mezzo'], 'km_totali': item['KmTotali']}
  File "/opt/airflow/dags/api_dag.py", line 28, in <listcomp>
    normalized_csv_data = [{'idMezzo': item['Mezzo'], 'km_totali': item['KmTotali']}
TypeError: string indices must be integers
[2024-02-22T19:47:57.724+0000] {taskinstance.py:1138} INFO - Marking task as FAILED. dag_id=api_dag, task_id=transform_load_data_task, execution_date=20240222T194751, start_date=20240222T194757, end_date=20240222T194757
[2024-02-22T19:47:57.738+0000] {standard_task_runner.py:107} ERROR - Failed to execute job 342 for task transform_load_data_task (string indices must be integers; 2748)
[2024-02-22T19:47:57.760+0000] {local_task_job_runner.py:234} INFO - Task exited with return code 1
[2024-02-22T19:47:57.784+0000] {taskinstance.py:3280} INFO - 0 downstream tasks scheduled from follow-on schedule check
