[2024-02-18T19:19:54.093+0000] {taskinstance.py:1956} INFO - Dependencies all met for dep_context=non-requeueable deps ti=<TaskInstance: api_dag.load_data_task manual__2024-02-18T19:19:48.028022+00:00 [queued]>
[2024-02-18T19:19:54.101+0000] {taskinstance.py:1956} INFO - Dependencies all met for dep_context=requeueable deps ti=<TaskInstance: api_dag.load_data_task manual__2024-02-18T19:19:48.028022+00:00 [queued]>
[2024-02-18T19:19:54.101+0000] {taskinstance.py:2170} INFO - Starting attempt 1 of 1
[2024-02-18T19:19:54.114+0000] {taskinstance.py:2191} INFO - Executing <Task(PostgresOperator): load_data_task> on 2024-02-18 19:19:48.028022+00:00
[2024-02-18T19:19:54.119+0000] {standard_task_runner.py:60} INFO - Started process 3557 to run task
[2024-02-18T19:19:54.123+0000] {standard_task_runner.py:87} INFO - Running: ['***', 'tasks', 'run', 'api_dag', 'load_data_task', 'manual__2024-02-18T19:19:48.028022+00:00', '--job-id', '39', '--raw', '--subdir', 'DAGS_FOLDER/api_dag.py', '--cfg-path', '/tmp/tmp0weu63ge']
[2024-02-18T19:19:54.125+0000] {standard_task_runner.py:88} INFO - Job 39: Subtask load_data_task
[2024-02-18T19:19:54.169+0000] {task_command.py:423} INFO - Running <TaskInstance: api_dag.load_data_task manual__2024-02-18T19:19:48.028022+00:00 [running]> on host 482b276ff4ae
[2024-02-18T19:19:54.249+0000] {taskinstance.py:2480} INFO - Exporting env vars: AIRFLOW_CTX_DAG_OWNER='***' AIRFLOW_CTX_DAG_ID='api_dag' AIRFLOW_CTX_TASK_ID='load_data_task' AIRFLOW_CTX_EXECUTION_DATE='2024-02-18T19:19:48.028022+00:00' AIRFLOW_CTX_TRY_NUMBER='1' AIRFLOW_CTX_DAG_RUN_ID='manual__2024-02-18T19:19:48.028022+00:00'
[2024-02-18T19:19:54.250+0000] {sql.py:276} INFO - Executing: <function load_data at 0x7f494849daf0>
[2024-02-18T19:19:54.261+0000] {base.py:83} INFO - Using connection ID 'postgres_conn' for task execution.
[2024-02-18T19:19:54.269+0000] {base.py:83} INFO - Using connection ID 'postgres_conn' for task execution.
[2024-02-18T19:19:55.755+0000] {taskinstance.py:2698} ERROR - Task failed with exception
Traceback (most recent call last):
  File "/home/airflow/.local/lib/python3.8/site-packages/airflow/models/taskinstance.py", line 433, in _execute_task
    result = execute_callable(context=context, **execute_callable_kwargs)
  File "/home/airflow/.local/lib/python3.8/site-packages/airflow/providers/common/sql/operators/sql.py", line 282, in execute
    output = hook.run(
  File "/home/airflow/.local/lib/python3.8/site-packages/airflow/providers/common/sql/hooks/sql.py", line 397, in run
    for sql_statement in sql_list:
TypeError: 'function' object is not iterable
[2024-02-18T19:19:55.769+0000] {taskinstance.py:1138} INFO - Marking task as FAILED. dag_id=api_dag, task_id=load_data_task, execution_date=20240218T191948, start_date=20240218T191954, end_date=20240218T191955
[2024-02-18T19:19:55.790+0000] {standard_task_runner.py:107} ERROR - Failed to execute job 39 for task load_data_task ('function' object is not iterable; 3557)
[2024-02-18T19:19:55.826+0000] {local_task_job_runner.py:234} INFO - Task exited with return code 1
[2024-02-18T19:19:55.859+0000] {taskinstance.py:3280} INFO - 0 downstream tasks scheduled from follow-on schedule check
