[2024-02-24T14:47:19.772+0000] {taskinstance.py:1956} INFO - Dependencies all met for dep_context=non-requeueable deps ti=<TaskInstance: api_dag.load_data_task manual__2024-02-24T14:47:12.002315+00:00 [queued]>
[2024-02-24T14:47:19.781+0000] {taskinstance.py:1956} INFO - Dependencies all met for dep_context=requeueable deps ti=<TaskInstance: api_dag.load_data_task manual__2024-02-24T14:47:12.002315+00:00 [queued]>
[2024-02-24T14:47:19.781+0000] {taskinstance.py:2170} INFO - Starting attempt 1 of 1
[2024-02-24T14:47:19.795+0000] {taskinstance.py:2191} INFO - Executing <Task(PythonOperator): load_data_task> on 2024-02-24 14:47:12.002315+00:00
[2024-02-24T14:47:19.802+0000] {standard_task_runner.py:60} INFO - Started process 337 to run task
[2024-02-24T14:47:19.806+0000] {standard_task_runner.py:87} INFO - Running: ['***', 'tasks', 'run', 'api_dag', 'load_data_task', 'manual__2024-02-24T14:47:12.002315+00:00', '--job-id', '630', '--raw', '--subdir', 'DAGS_FOLDER/api_dag.py', '--cfg-path', '/tmp/tmp4ysxzllb']
[2024-02-24T14:47:19.807+0000] {standard_task_runner.py:88} INFO - Job 630: Subtask load_data_task
[2024-02-24T14:47:19.849+0000] {task_command.py:423} INFO - Running <TaskInstance: api_dag.load_data_task manual__2024-02-24T14:47:12.002315+00:00 [running]> on host 614a08523528
[2024-02-24T14:47:19.919+0000] {taskinstance.py:2480} INFO - Exporting env vars: AIRFLOW_CTX_DAG_OWNER='***' AIRFLOW_CTX_DAG_ID='api_dag' AIRFLOW_CTX_TASK_ID='load_data_task' AIRFLOW_CTX_EXECUTION_DATE='2024-02-24T14:47:12.002315+00:00' AIRFLOW_CTX_TRY_NUMBER='1' AIRFLOW_CTX_DAG_RUN_ID='manual__2024-02-24T14:47:12.002315+00:00'
[2024-02-24T14:47:19.929+0000] {taskinstance.py:2698} ERROR - Task failed with exception
Traceback (most recent call last):
  File "/home/airflow/.local/lib/python3.8/site-packages/airflow/models/taskinstance.py", line 433, in _execute_task
    result = execute_callable(context=context, **execute_callable_kwargs)
  File "/home/airflow/.local/lib/python3.8/site-packages/airflow/operators/python.py", line 199, in execute
    return_value = self.execute_callable()
  File "/home/airflow/.local/lib/python3.8/site-packages/airflow/operators/python.py", line 216, in execute_callable
    return self.python_callable(*self.op_args, **self.op_kwargs)
  File "/opt/airflow/dags/api_dag.py", line 37, in load_data
    data_to_load.to_sql('automezzo', db, if_exists='replace', dtype=dtypes)
AttributeError: 'list' object has no attribute 'to_sql'
[2024-02-24T14:47:19.936+0000] {taskinstance.py:1138} INFO - Marking task as FAILED. dag_id=api_dag, task_id=load_data_task, execution_date=20240224T144712, start_date=20240224T144719, end_date=20240224T144719
[2024-02-24T14:47:19.947+0000] {standard_task_runner.py:107} ERROR - Failed to execute job 630 for task load_data_task ('list' object has no attribute 'to_sql'; 337)
[2024-02-24T14:47:19.978+0000] {local_task_job_runner.py:234} INFO - Task exited with return code 1
[2024-02-24T14:47:19.993+0000] {taskinstance.py:3280} INFO - 0 downstream tasks scheduled from follow-on schedule check
