[2024-02-22T19:03:54.983+0000] {taskinstance.py:1956} INFO - Dependencies all met for dep_context=non-requeueable deps ti=<TaskInstance: api_dag.transform_load_data_task manual__2024-02-22T19:03:49.199719+00:00 [queued]>
[2024-02-22T19:03:54.991+0000] {taskinstance.py:1956} INFO - Dependencies all met for dep_context=requeueable deps ti=<TaskInstance: api_dag.transform_load_data_task manual__2024-02-22T19:03:49.199719+00:00 [queued]>
[2024-02-22T19:03:54.991+0000] {taskinstance.py:2170} INFO - Starting attempt 1 of 1
[2024-02-22T19:03:55.004+0000] {taskinstance.py:2191} INFO - Executing <Task(PythonOperator): transform_load_data_task> on 2024-02-22 19:03:49.199719+00:00
[2024-02-22T19:03:55.009+0000] {standard_task_runner.py:60} INFO - Started process 1776 to run task
[2024-02-22T19:03:55.013+0000] {standard_task_runner.py:87} INFO - Running: ['***', 'tasks', 'run', 'api_dag', 'transform_load_data_task', 'manual__2024-02-22T19:03:49.199719+00:00', '--job-id', '289', '--raw', '--subdir', 'DAGS_FOLDER/api_dag.py', '--cfg-path', '/tmp/tmpm7arfpr3']
[2024-02-22T19:03:55.014+0000] {standard_task_runner.py:88} INFO - Job 289: Subtask transform_load_data_task
[2024-02-22T19:03:55.056+0000] {task_command.py:423} INFO - Running <TaskInstance: api_dag.transform_load_data_task manual__2024-02-22T19:03:49.199719+00:00 [running]> on host 614a08523528
[2024-02-22T19:03:55.129+0000] {taskinstance.py:2480} INFO - Exporting env vars: AIRFLOW_CTX_DAG_OWNER='***' AIRFLOW_CTX_DAG_ID='api_dag' AIRFLOW_CTX_TASK_ID='transform_load_data_task' AIRFLOW_CTX_EXECUTION_DATE='2024-02-22T19:03:49.199719+00:00' AIRFLOW_CTX_TRY_NUMBER='1' AIRFLOW_CTX_DAG_RUN_ID='manual__2024-02-22T19:03:49.199719+00:00'
[2024-02-22T19:03:55.179+0000] {taskinstance.py:2698} ERROR - Task failed with exception
Traceback (most recent call last):
  File "/home/airflow/.local/lib/python3.8/site-packages/airflow/models/taskinstance.py", line 433, in _execute_task
    result = execute_callable(context=context, **execute_callable_kwargs)
  File "/home/airflow/.local/lib/python3.8/site-packages/airflow/operators/python.py", line 199, in execute
    return_value = self.execute_callable()
  File "/home/airflow/.local/lib/python3.8/site-packages/airflow/operators/python.py", line 216, in execute_callable
    return self.python_callable(*self.op_args, **self.op_kwargs)
  File "/opt/airflow/dags/api_dag.py", line 28, in transform_data
    normalized_csv_data = [{'idMezzo': item[csv_column_mapping['Mezzo']], 'km_totali': item[csv_column_mapping['Km Totali (km)']]}
  File "/opt/airflow/dags/api_dag.py", line 28, in <listcomp>
    normalized_csv_data = [{'idMezzo': item[csv_column_mapping['Mezzo']], 'km_totali': item[csv_column_mapping['Km Totali (km)']]}
TypeError: string indices must be integers
[2024-02-22T19:03:55.186+0000] {taskinstance.py:1138} INFO - Marking task as FAILED. dag_id=api_dag, task_id=transform_load_data_task, execution_date=20240222T190349, start_date=20240222T190354, end_date=20240222T190355
[2024-02-22T19:03:55.197+0000] {standard_task_runner.py:107} ERROR - Failed to execute job 289 for task transform_load_data_task (string indices must be integers; 1776)
[2024-02-22T19:03:55.225+0000] {local_task_job_runner.py:234} INFO - Task exited with return code 1
[2024-02-22T19:03:55.248+0000] {taskinstance.py:3280} INFO - 0 downstream tasks scheduled from follow-on schedule check
