[2024-02-24T10:12:40.843+0000] {taskinstance.py:1956} INFO - Dependencies all met for dep_context=non-requeueable deps ti=<TaskInstance: api_dag.transform_load_data_task manual__2024-02-24T10:12:36.464155+00:00 [queued]>
[2024-02-24T10:12:40.848+0000] {taskinstance.py:1956} INFO - Dependencies all met for dep_context=requeueable deps ti=<TaskInstance: api_dag.transform_load_data_task manual__2024-02-24T10:12:36.464155+00:00 [queued]>
[2024-02-24T10:12:40.848+0000] {taskinstance.py:2170} INFO - Starting attempt 1 of 1
[2024-02-24T10:12:40.856+0000] {taskinstance.py:2191} INFO - Executing <Task(PythonOperator): transform_load_data_task> on 2024-02-24 10:12:36.464155+00:00
[2024-02-24T10:12:40.861+0000] {standard_task_runner.py:60} INFO - Started process 598 to run task
[2024-02-24T10:12:40.863+0000] {standard_task_runner.py:87} INFO - Running: ['***', 'tasks', 'run', 'api_dag', 'transform_load_data_task', 'manual__2024-02-24T10:12:36.464155+00:00', '--job-id', '480', '--raw', '--subdir', 'DAGS_FOLDER/api_dag.py', '--cfg-path', '/tmp/tmp6dr4zset']
[2024-02-24T10:12:40.864+0000] {standard_task_runner.py:88} INFO - Job 480: Subtask transform_load_data_task
[2024-02-24T10:12:40.894+0000] {task_command.py:423} INFO - Running <TaskInstance: api_dag.transform_load_data_task manual__2024-02-24T10:12:36.464155+00:00 [running]> on host 614a08523528
[2024-02-24T10:12:40.942+0000] {taskinstance.py:2480} INFO - Exporting env vars: AIRFLOW_CTX_DAG_OWNER='***' AIRFLOW_CTX_DAG_ID='api_dag' AIRFLOW_CTX_TASK_ID='transform_load_data_task' AIRFLOW_CTX_EXECUTION_DATE='2024-02-24T10:12:36.464155+00:00' AIRFLOW_CTX_TRY_NUMBER='1' AIRFLOW_CTX_DAG_RUN_ID='manual__2024-02-24T10:12:36.464155+00:00'
[2024-02-24T10:12:40.976+0000] {taskinstance.py:2698} ERROR - Task failed with exception
Traceback (most recent call last):
  File "/home/airflow/.local/lib/python3.8/site-packages/airflow/models/taskinstance.py", line 433, in _execute_task
    result = execute_callable(context=context, **execute_callable_kwargs)
  File "/home/airflow/.local/lib/python3.8/site-packages/airflow/operators/python.py", line 199, in execute
    return_value = self.execute_callable()
  File "/home/airflow/.local/lib/python3.8/site-packages/airflow/operators/python.py", line 216, in execute_callable
    return self.python_callable(*self.op_args, **self.op_kwargs)
  File "/opt/airflow/dags/api_dag.py", line 32, in transform_data
    selected_data = merged_data.loc[[1, 2]]
  File "/home/airflow/.local/lib/python3.8/site-packages/pandas/core/indexing.py", line 1103, in __getitem__
    return self._getitem_axis(maybe_callable, axis=axis)
  File "/home/airflow/.local/lib/python3.8/site-packages/pandas/core/indexing.py", line 1332, in _getitem_axis
    return self._getitem_iterable(key, axis=axis)
  File "/home/airflow/.local/lib/python3.8/site-packages/pandas/core/indexing.py", line 1272, in _getitem_iterable
    keyarr, indexer = self._get_listlike_indexer(key, axis)
  File "/home/airflow/.local/lib/python3.8/site-packages/pandas/core/indexing.py", line 1462, in _get_listlike_indexer
    keyarr, indexer = ax._get_indexer_strict(key, axis_name)
  File "/home/airflow/.local/lib/python3.8/site-packages/pandas/core/indexes/base.py", line 5877, in _get_indexer_strict
    self._raise_if_missing(keyarr, indexer, axis_name)
  File "/home/airflow/.local/lib/python3.8/site-packages/pandas/core/indexes/base.py", line 5938, in _raise_if_missing
    raise KeyError(f"None of [{key}] are in the [{axis_name}]")
KeyError: "None of [Index([1, 2], dtype='int64')] are in the [index]"
[2024-02-24T10:12:40.983+0000] {taskinstance.py:1138} INFO - Marking task as FAILED. dag_id=api_dag, task_id=transform_load_data_task, execution_date=20240224T101236, start_date=20240224T101240, end_date=20240224T101240
[2024-02-24T10:12:40.990+0000] {standard_task_runner.py:107} ERROR - Failed to execute job 480 for task transform_load_data_task ("None of [Index([1, 2], dtype='int64')] are in the [index]"; 598)
[2024-02-24T10:12:41.036+0000] {local_task_job_runner.py:234} INFO - Task exited with return code 1
[2024-02-24T10:12:41.058+0000] {taskinstance.py:3280} INFO - 0 downstream tasks scheduled from follow-on schedule check
