[2024-02-24T17:41:46.787+0000] {taskinstance.py:1956} INFO - Dependencies all met for dep_context=non-requeueable deps ti=<TaskInstance: api_dag.transform_data_task manual__2024-02-24T17:41:41.630950+00:00 [queued]>
[2024-02-24T17:41:46.792+0000] {taskinstance.py:1956} INFO - Dependencies all met for dep_context=requeueable deps ti=<TaskInstance: api_dag.transform_data_task manual__2024-02-24T17:41:41.630950+00:00 [queued]>
[2024-02-24T17:41:46.792+0000] {taskinstance.py:2170} INFO - Starting attempt 1 of 1
[2024-02-24T17:41:46.800+0000] {taskinstance.py:2191} INFO - Executing <Task(PythonOperator): transform_data_task> on 2024-02-24 17:41:41.630950+00:00
[2024-02-24T17:41:46.806+0000] {standard_task_runner.py:60} INFO - Started process 4482 to run task
[2024-02-24T17:41:46.808+0000] {standard_task_runner.py:87} INFO - Running: ['***', 'tasks', 'run', 'api_dag', 'transform_data_task', 'manual__2024-02-24T17:41:41.630950+00:00', '--job-id', '852', '--raw', '--subdir', 'DAGS_FOLDER/api_dag.py', '--cfg-path', '/tmp/tmpp6mmoiyu']
[2024-02-24T17:41:46.808+0000] {standard_task_runner.py:88} INFO - Job 852: Subtask transform_data_task
[2024-02-24T17:41:46.840+0000] {task_command.py:423} INFO - Running <TaskInstance: api_dag.transform_data_task manual__2024-02-24T17:41:41.630950+00:00 [running]> on host 614a08523528
[2024-02-24T17:41:46.889+0000] {taskinstance.py:2480} INFO - Exporting env vars: AIRFLOW_CTX_DAG_OWNER='***' AIRFLOW_CTX_DAG_ID='api_dag' AIRFLOW_CTX_TASK_ID='transform_data_task' AIRFLOW_CTX_EXECUTION_DATE='2024-02-24T17:41:41.630950+00:00' AIRFLOW_CTX_TRY_NUMBER='1' AIRFLOW_CTX_DAG_RUN_ID='manual__2024-02-24T17:41:41.630950+00:00'
[2024-02-24T17:41:46.944+0000] {taskinstance.py:2698} ERROR - Task failed with exception
Traceback (most recent call last):
  File "/home/airflow/.local/lib/python3.8/site-packages/airflow/models/taskinstance.py", line 433, in _execute_task
    result = execute_callable(context=context, **execute_callable_kwargs)
  File "/home/airflow/.local/lib/python3.8/site-packages/airflow/operators/python.py", line 199, in execute
    return_value = self.execute_callable()
  File "/home/airflow/.local/lib/python3.8/site-packages/airflow/operators/python.py", line 216, in execute_callable
    return self.python_callable(*self.op_args, **self.op_kwargs)
  File "/opt/airflow/dags/api_dag.py", line 45, in transform_data
    merged_data = pd.concat([selected_csv1, selected_csv4, selected_csv3, selected_csv2, transformed_api], ignore_index=True)
  File "/home/airflow/.local/lib/python3.8/site-packages/pandas/core/reshape/concat.py", line 372, in concat
    op = _Concatenator(
  File "/home/airflow/.local/lib/python3.8/site-packages/pandas/core/reshape/concat.py", line 462, in __init__
    raise TypeError(msg)
TypeError: cannot concatenate object of type '<class 'list'>'; only Series and DataFrame objs are valid
[2024-02-24T17:41:46.950+0000] {taskinstance.py:1138} INFO - Marking task as FAILED. dag_id=api_dag, task_id=transform_data_task, execution_date=20240224T174141, start_date=20240224T174146, end_date=20240224T174146
[2024-02-24T17:41:46.959+0000] {standard_task_runner.py:107} ERROR - Failed to execute job 852 for task transform_data_task (cannot concatenate object of type '<class 'list'>'; only Series and DataFrame objs are valid; 4482)
[2024-02-24T17:41:46.982+0000] {local_task_job_runner.py:234} INFO - Task exited with return code 1
[2024-02-24T17:41:46.994+0000] {taskinstance.py:3280} INFO - 0 downstream tasks scheduled from follow-on schedule check
