[2024-02-18T21:49:12.470+0000] {taskinstance.py:1956} INFO - Dependencies all met for dep_context=non-requeueable deps ti=<TaskInstance: api_dag.transform_data_task manual__2024-02-18T21:49:09.888315+00:00 [queued]>
[2024-02-18T21:49:12.476+0000] {taskinstance.py:1956} INFO - Dependencies all met for dep_context=requeueable deps ti=<TaskInstance: api_dag.transform_data_task manual__2024-02-18T21:49:09.888315+00:00 [queued]>
[2024-02-18T21:49:12.477+0000] {taskinstance.py:2170} INFO - Starting attempt 1 of 1
[2024-02-18T21:49:12.485+0000] {taskinstance.py:2191} INFO - Executing <Task(PythonOperator): transform_data_task> on 2024-02-18 21:49:09.888315+00:00
[2024-02-18T21:49:12.490+0000] {standard_task_runner.py:60} INFO - Started process 6173 to run task
[2024-02-18T21:49:12.493+0000] {standard_task_runner.py:87} INFO - Running: ['***', 'tasks', 'run', 'api_dag', 'transform_data_task', 'manual__2024-02-18T21:49:09.888315+00:00', '--job-id', '161', '--raw', '--subdir', 'DAGS_FOLDER/api_dag.py', '--cfg-path', '/tmp/tmpl269uyav']
[2024-02-18T21:49:12.494+0000] {standard_task_runner.py:88} INFO - Job 161: Subtask transform_data_task
[2024-02-18T21:49:12.525+0000] {task_command.py:423} INFO - Running <TaskInstance: api_dag.transform_data_task manual__2024-02-18T21:49:09.888315+00:00 [running]> on host 482b276ff4ae
[2024-02-18T21:49:12.578+0000] {taskinstance.py:2480} INFO - Exporting env vars: AIRFLOW_CTX_DAG_OWNER='***' AIRFLOW_CTX_DAG_ID='api_dag' AIRFLOW_CTX_TASK_ID='transform_data_task' AIRFLOW_CTX_EXECUTION_DATE='2024-02-18T21:49:09.888315+00:00' AIRFLOW_CTX_TRY_NUMBER='1' AIRFLOW_CTX_DAG_RUN_ID='manual__2024-02-18T21:49:09.888315+00:00'
[2024-02-18T21:49:12.596+0000] {taskinstance.py:2698} ERROR - Task failed with exception
Traceback (most recent call last):
  File "/home/airflow/.local/lib/python3.8/site-packages/airflow/models/taskinstance.py", line 433, in _execute_task
    result = execute_callable(context=context, **execute_callable_kwargs)
  File "/home/airflow/.local/lib/python3.8/site-packages/airflow/operators/python.py", line 199, in execute
    return_value = self.execute_callable()
  File "/home/airflow/.local/lib/python3.8/site-packages/airflow/operators/python.py", line 216, in execute_callable
    return self.python_callable(*self.op_args, **self.op_kwargs)
  File "/opt/airflow/dags/api_dag.py", line 21, in transform_data
    engine = create_engine("postgres://flnjdqme:gQeyQIGRJTOtzrwmqa78m7YqeBfeiWOz@dumbo.db.elephantsql.com/flnjdqme")
  File "<string>", line 2, in create_engine
  File "/home/airflow/.local/lib/python3.8/site-packages/sqlalchemy/util/deprecations.py", line 375, in warned
    return fn(*args, **kwargs)
  File "/home/airflow/.local/lib/python3.8/site-packages/sqlalchemy/engine/create.py", line 518, in create_engine
    entrypoint = u._get_entrypoint()
  File "/home/airflow/.local/lib/python3.8/site-packages/sqlalchemy/engine/url.py", line 662, in _get_entrypoint
    cls = registry.load(name)
  File "/home/airflow/.local/lib/python3.8/site-packages/sqlalchemy/util/langhelpers.py", line 343, in load
    raise exc.NoSuchModuleError(
sqlalchemy.exc.NoSuchModuleError: Can't load plugin: sqlalchemy.dialects:postgres
[2024-02-18T21:49:12.601+0000] {taskinstance.py:1138} INFO - Marking task as FAILED. dag_id=api_dag, task_id=transform_data_task, execution_date=20240218T214909, start_date=20240218T214912, end_date=20240218T214912
[2024-02-18T21:49:12.609+0000] {standard_task_runner.py:107} ERROR - Failed to execute job 161 for task transform_data_task (Can't load plugin: sqlalchemy.dialects:postgres; 6173)
[2024-02-18T21:49:12.624+0000] {local_task_job_runner.py:234} INFO - Task exited with return code 1
[2024-02-18T21:49:12.635+0000] {taskinstance.py:3280} INFO - 0 downstream tasks scheduled from follow-on schedule check
