[2024-02-22T19:17:16.678+0000] {taskinstance.py:1956} INFO - Dependencies all met for dep_context=non-requeueable deps ti=<TaskInstance: api_dag.transform_load_data_task manual__2024-02-22T19:17:11.024814+00:00 [queued]>
[2024-02-22T19:17:16.686+0000] {taskinstance.py:1956} INFO - Dependencies all met for dep_context=requeueable deps ti=<TaskInstance: api_dag.transform_load_data_task manual__2024-02-22T19:17:11.024814+00:00 [queued]>
[2024-02-22T19:17:16.686+0000] {taskinstance.py:2170} INFO - Starting attempt 1 of 1
[2024-02-22T19:17:16.698+0000] {taskinstance.py:2191} INFO - Executing <Task(PythonOperator): transform_load_data_task> on 2024-02-22 19:17:11.024814+00:00
[2024-02-22T19:17:16.704+0000] {standard_task_runner.py:60} INFO - Started process 2104 to run task
[2024-02-22T19:17:16.707+0000] {standard_task_runner.py:87} INFO - Running: ['***', 'tasks', 'run', 'api_dag', 'transform_load_data_task', 'manual__2024-02-22T19:17:11.024814+00:00', '--job-id', '309', '--raw', '--subdir', 'DAGS_FOLDER/api_dag.py', '--cfg-path', '/tmp/tmpa1pfb93l']
[2024-02-22T19:17:16.708+0000] {standard_task_runner.py:88} INFO - Job 309: Subtask transform_load_data_task
[2024-02-22T19:17:16.752+0000] {task_command.py:423} INFO - Running <TaskInstance: api_dag.transform_load_data_task manual__2024-02-22T19:17:11.024814+00:00 [running]> on host 614a08523528
[2024-02-22T19:17:16.822+0000] {taskinstance.py:2480} INFO - Exporting env vars: AIRFLOW_CTX_DAG_OWNER='***' AIRFLOW_CTX_DAG_ID='api_dag' AIRFLOW_CTX_TASK_ID='transform_load_data_task' AIRFLOW_CTX_EXECUTION_DATE='2024-02-22T19:17:11.024814+00:00' AIRFLOW_CTX_TRY_NUMBER='1' AIRFLOW_CTX_DAG_RUN_ID='manual__2024-02-22T19:17:11.024814+00:00'
[2024-02-22T19:17:16.869+0000] {taskinstance.py:2698} ERROR - Task failed with exception
Traceback (most recent call last):
  File "/home/airflow/.local/lib/python3.8/site-packages/airflow/models/taskinstance.py", line 433, in _execute_task
    result = execute_callable(context=context, **execute_callable_kwargs)
  File "/home/airflow/.local/lib/python3.8/site-packages/airflow/operators/python.py", line 199, in execute
    return_value = self.execute_callable()
  File "/home/airflow/.local/lib/python3.8/site-packages/airflow/operators/python.py", line 216, in execute_callable
    return self.python_callable(*self.op_args, **self.op_kwargs)
  File "/opt/airflow/dags/api_dag.py", line 28, in transform_data
    normalized_csv_data = [{'idMezzo': item[csv_column_mapping['Mezzo']], 'km_totali': item[csv_column_mapping['KmTotali']]}
  File "/opt/airflow/dags/api_dag.py", line 28, in <listcomp>
    normalized_csv_data = [{'idMezzo': item[csv_column_mapping['Mezzo']], 'km_totali': item[csv_column_mapping['KmTotali']]}
TypeError: string indices must be integers
[2024-02-22T19:17:16.877+0000] {taskinstance.py:1138} INFO - Marking task as FAILED. dag_id=api_dag, task_id=transform_load_data_task, execution_date=20240222T191711, start_date=20240222T191716, end_date=20240222T191716
[2024-02-22T19:17:16.889+0000] {standard_task_runner.py:107} ERROR - Failed to execute job 309 for task transform_load_data_task (string indices must be integers; 2104)
[2024-02-22T19:17:16.919+0000] {local_task_job_runner.py:234} INFO - Task exited with return code 1
[2024-02-22T19:17:16.936+0000] {taskinstance.py:3280} INFO - 0 downstream tasks scheduled from follow-on schedule check
