[2024-02-18T19:51:40.553+0000] {taskinstance.py:1956} INFO - Dependencies all met for dep_context=non-requeueable deps ti=<TaskInstance: api_dag.insert_into_postgres manual__2024-02-18T19:51:34.737968+00:00 [queued]>
[2024-02-18T19:51:40.560+0000] {taskinstance.py:1956} INFO - Dependencies all met for dep_context=requeueable deps ti=<TaskInstance: api_dag.insert_into_postgres manual__2024-02-18T19:51:34.737968+00:00 [queued]>
[2024-02-18T19:51:40.560+0000] {taskinstance.py:2170} INFO - Starting attempt 1 of 1
[2024-02-18T19:51:40.571+0000] {taskinstance.py:2191} INFO - Executing <Task(PostgresOperator): insert_into_postgres> on 2024-02-18 19:51:34.737968+00:00
[2024-02-18T19:51:40.576+0000] {standard_task_runner.py:60} INFO - Started process 4114 to run task
[2024-02-18T19:51:40.579+0000] {standard_task_runner.py:87} INFO - Running: ['***', 'tasks', 'run', 'api_dag', 'insert_into_postgres', 'manual__2024-02-18T19:51:34.737968+00:00', '--job-id', '68', '--raw', '--subdir', 'DAGS_FOLDER/api_dag.py', '--cfg-path', '/tmp/tmp48z2nquc']
[2024-02-18T19:51:40.580+0000] {standard_task_runner.py:88} INFO - Job 68: Subtask insert_into_postgres
[2024-02-18T19:51:40.628+0000] {task_command.py:423} INFO - Running <TaskInstance: api_dag.insert_into_postgres manual__2024-02-18T19:51:34.737968+00:00 [running]> on host 482b276ff4ae
[2024-02-18T19:51:40.685+0000] {abstractoperator.py:707} ERROR - Exception rendering Jinja template for task 'insert_into_postgres', field 'parameters'. Template: {'param_id': "{{ task_instance.xcom_pull(task_ids='transform_data_task')[0]['idServizio'] }}"}
Traceback (most recent call last):
  File "/home/airflow/.local/lib/python3.8/site-packages/airflow/models/abstractoperator.py", line 699, in _do_render_template_fields
    rendered_content = self.render_template(
  File "/home/airflow/.local/lib/python3.8/site-packages/airflow/template/templater.py", line 186, in render_template
    return {k: self.render_template(v, context, jinja_env, oids) for k, v in value.items()}
  File "/home/airflow/.local/lib/python3.8/site-packages/airflow/template/templater.py", line 186, in <dictcomp>
    return {k: self.render_template(v, context, jinja_env, oids) for k, v in value.items()}
  File "/home/airflow/.local/lib/python3.8/site-packages/airflow/template/templater.py", line 174, in render_template
    return self._render(template, context)
  File "/home/airflow/.local/lib/python3.8/site-packages/airflow/models/abstractoperator.py", line 654, in _render
    return super()._render(template, context, dag=dag)
  File "/home/airflow/.local/lib/python3.8/site-packages/airflow/template/templater.py", line 131, in _render
    return render_template_to_string(template, context)
  File "/home/airflow/.local/lib/python3.8/site-packages/airflow/utils/helpers.py", line 289, in render_template_to_string
    return render_template(template, cast(MutableMapping[str, Any], context), native=False)
  File "/home/airflow/.local/lib/python3.8/site-packages/airflow/utils/helpers.py", line 284, in render_template
    return "".join(nodes)
  File "<template>", line 12, in root
  File "/home/airflow/.local/lib/python3.8/site-packages/jinja2/sandbox.py", line 303, in getitem
    return obj[argument]
  File "/home/airflow/.local/lib/python3.8/site-packages/jinja2/runtime.py", line 852, in _fail_with_undefined_error
    raise self._undefined_exception(self._undefined_message)
jinja2.exceptions.UndefinedError: None has no element 0
[2024-02-18T19:51:40.687+0000] {taskinstance.py:2698} ERROR - Task failed with exception
Traceback (most recent call last):
  File "/home/airflow/.local/lib/python3.8/site-packages/airflow/models/taskinstance.py", line 2334, in _run_raw_task
    self._execute_task_with_callbacks(context, test_mode, session=session)
  File "/home/airflow/.local/lib/python3.8/site-packages/airflow/models/taskinstance.py", line 2465, in _execute_task_with_callbacks
    task_orig = self.render_templates(context=context)
  File "/home/airflow/.local/lib/python3.8/site-packages/airflow/models/taskinstance.py", line 2877, in render_templates
    original_task.render_template_fields(context)
  File "/home/airflow/.local/lib/python3.8/site-packages/airflow/models/baseoperator.py", line 1241, in render_template_fields
    self._do_render_template_fields(self, self.template_fields, context, jinja_env, set())
  File "/home/airflow/.local/lib/python3.8/site-packages/airflow/utils/session.py", line 79, in wrapper
    return func(*args, session=session, **kwargs)
  File "/home/airflow/.local/lib/python3.8/site-packages/airflow/models/abstractoperator.py", line 699, in _do_render_template_fields
    rendered_content = self.render_template(
  File "/home/airflow/.local/lib/python3.8/site-packages/airflow/template/templater.py", line 186, in render_template
    return {k: self.render_template(v, context, jinja_env, oids) for k, v in value.items()}
  File "/home/airflow/.local/lib/python3.8/site-packages/airflow/template/templater.py", line 186, in <dictcomp>
    return {k: self.render_template(v, context, jinja_env, oids) for k, v in value.items()}
  File "/home/airflow/.local/lib/python3.8/site-packages/airflow/template/templater.py", line 174, in render_template
    return self._render(template, context)
  File "/home/airflow/.local/lib/python3.8/site-packages/airflow/models/abstractoperator.py", line 654, in _render
    return super()._render(template, context, dag=dag)
  File "/home/airflow/.local/lib/python3.8/site-packages/airflow/template/templater.py", line 131, in _render
    return render_template_to_string(template, context)
  File "/home/airflow/.local/lib/python3.8/site-packages/airflow/utils/helpers.py", line 289, in render_template_to_string
    return render_template(template, cast(MutableMapping[str, Any], context), native=False)
  File "/home/airflow/.local/lib/python3.8/site-packages/airflow/utils/helpers.py", line 284, in render_template
    return "".join(nodes)
  File "<template>", line 12, in root
  File "/home/airflow/.local/lib/python3.8/site-packages/jinja2/sandbox.py", line 303, in getitem
    return obj[argument]
  File "/home/airflow/.local/lib/python3.8/site-packages/jinja2/runtime.py", line 852, in _fail_with_undefined_error
    raise self._undefined_exception(self._undefined_message)
jinja2.exceptions.UndefinedError: None has no element 0
[2024-02-18T19:51:40.693+0000] {taskinstance.py:1138} INFO - Marking task as FAILED. dag_id=api_dag, task_id=insert_into_postgres, execution_date=20240218T195134, start_date=20240218T195140, end_date=20240218T195140
[2024-02-18T19:51:40.703+0000] {standard_task_runner.py:107} ERROR - Failed to execute job 68 for task insert_into_postgres (None has no element 0; 4114)
[2024-02-18T19:51:40.711+0000] {local_task_job_runner.py:234} INFO - Task exited with return code 1
[2024-02-18T19:51:40.726+0000] {taskinstance.py:3280} INFO - 0 downstream tasks scheduled from follow-on schedule check
