[2024-02-22T20:10:13.976+0000] {taskinstance.py:1956} INFO - Dependencies all met for dep_context=non-requeueable deps ti=<TaskInstance: api_dag.transform_load_data_task manual__2024-02-22T20:10:07.674495+00:00 [queued]>
[2024-02-22T20:10:13.983+0000] {taskinstance.py:1956} INFO - Dependencies all met for dep_context=requeueable deps ti=<TaskInstance: api_dag.transform_load_data_task manual__2024-02-22T20:10:07.674495+00:00 [queued]>
[2024-02-22T20:10:13.983+0000] {taskinstance.py:2170} INFO - Starting attempt 1 of 1
[2024-02-22T20:10:13.996+0000] {taskinstance.py:2191} INFO - Executing <Task(PythonOperator): transform_load_data_task> on 2024-02-22 20:10:07.674495+00:00
[2024-02-22T20:10:14.002+0000] {standard_task_runner.py:60} INFO - Started process 3288 to run task
[2024-02-22T20:10:14.005+0000] {standard_task_runner.py:87} INFO - Running: ['***', 'tasks', 'run', 'api_dag', 'transform_load_data_task', 'manual__2024-02-22T20:10:07.674495+00:00', '--job-id', '375', '--raw', '--subdir', 'DAGS_FOLDER/api_dag.py', '--cfg-path', '/tmp/tmpwxbqx1pl']
[2024-02-22T20:10:14.006+0000] {standard_task_runner.py:88} INFO - Job 375: Subtask transform_load_data_task
[2024-02-22T20:10:14.048+0000] {task_command.py:423} INFO - Running <TaskInstance: api_dag.transform_load_data_task manual__2024-02-22T20:10:07.674495+00:00 [running]> on host 614a08523528
[2024-02-22T20:10:14.113+0000] {taskinstance.py:2480} INFO - Exporting env vars: AIRFLOW_CTX_DAG_OWNER='***' AIRFLOW_CTX_DAG_ID='api_dag' AIRFLOW_CTX_TASK_ID='transform_load_data_task' AIRFLOW_CTX_EXECUTION_DATE='2024-02-22T20:10:07.674495+00:00' AIRFLOW_CTX_TRY_NUMBER='1' AIRFLOW_CTX_DAG_RUN_ID='manual__2024-02-22T20:10:07.674495+00:00'
[2024-02-22T20:10:14.163+0000] {logging_mixin.py:188} INFO - idMezzo
[2024-02-22T20:10:14.164+0000] {logging_mixin.py:188} INFO - idMezzo
[2024-02-22T20:10:14.164+0000] {taskinstance.py:2698} ERROR - Task failed with exception
Traceback (most recent call last):
  File "/home/airflow/.local/lib/python3.8/site-packages/airflow/models/taskinstance.py", line 433, in _execute_task
    result = execute_callable(context=context, **execute_callable_kwargs)
  File "/home/airflow/.local/lib/python3.8/site-packages/airflow/operators/python.py", line 199, in execute
    return_value = self.execute_callable()
  File "/home/airflow/.local/lib/python3.8/site-packages/airflow/operators/python.py", line 216, in execute_callable
    return self.python_callable(*self.op_args, **self.op_kwargs)
  File "/opt/airflow/dags/api_dag.py", line 30, in transform_data
    normalized_csv_data = [{'idMezzo': item['Mezzo'], 'km_totali': item['KmTotali']}
  File "/opt/airflow/dags/api_dag.py", line 30, in <listcomp>
    normalized_csv_data = [{'idMezzo': item['Mezzo'], 'km_totali': item['KmTotali']}
TypeError: string indices must be integers
[2024-02-22T20:10:14.171+0000] {taskinstance.py:1138} INFO - Marking task as FAILED. dag_id=api_dag, task_id=transform_load_data_task, execution_date=20240222T201007, start_date=20240222T201013, end_date=20240222T201014
[2024-02-22T20:10:14.182+0000] {standard_task_runner.py:107} ERROR - Failed to execute job 375 for task transform_load_data_task (string indices must be integers; 3288)
[2024-02-22T20:10:14.218+0000] {local_task_job_runner.py:234} INFO - Task exited with return code 1
[2024-02-22T20:10:14.244+0000] {taskinstance.py:3280} INFO - 0 downstream tasks scheduled from follow-on schedule check
