[2024-02-18T19:06:44.404+0000] {taskinstance.py:1956} INFO - Dependencies all met for dep_context=non-requeueable deps ti=<TaskInstance: api_dag.load_data_task manual__2024-02-18T19:06:39.103321+00:00 [queued]>
[2024-02-18T19:06:44.415+0000] {taskinstance.py:1956} INFO - Dependencies all met for dep_context=requeueable deps ti=<TaskInstance: api_dag.load_data_task manual__2024-02-18T19:06:39.103321+00:00 [queued]>
[2024-02-18T19:06:44.416+0000] {taskinstance.py:2170} INFO - Starting attempt 1 of 1
[2024-02-18T19:06:44.428+0000] {taskinstance.py:2191} INFO - Executing <Task(PostgresOperator): load_data_task> on 2024-02-18 19:06:39.103321+00:00
[2024-02-18T19:06:44.432+0000] {standard_task_runner.py:60} INFO - Started process 3334 to run task
[2024-02-18T19:06:44.435+0000] {standard_task_runner.py:87} INFO - Running: ['***', 'tasks', 'run', 'api_dag', 'load_data_task', 'manual__2024-02-18T19:06:39.103321+00:00', '--job-id', '30', '--raw', '--subdir', 'DAGS_FOLDER/api_dag.py', '--cfg-path', '/tmp/tmp7hv4_2_8']
[2024-02-18T19:06:44.436+0000] {standard_task_runner.py:88} INFO - Job 30: Subtask load_data_task
[2024-02-18T19:06:44.475+0000] {task_command.py:423} INFO - Running <TaskInstance: api_dag.load_data_task manual__2024-02-18T19:06:39.103321+00:00 [running]> on host 482b276ff4ae
[2024-02-18T19:06:44.546+0000] {taskinstance.py:2480} INFO - Exporting env vars: AIRFLOW_CTX_DAG_OWNER='***' AIRFLOW_CTX_DAG_ID='api_dag' AIRFLOW_CTX_TASK_ID='load_data_task' AIRFLOW_CTX_EXECUTION_DATE='2024-02-18T19:06:39.103321+00:00' AIRFLOW_CTX_TRY_NUMBER='1' AIRFLOW_CTX_DAG_RUN_ID='manual__2024-02-18T19:06:39.103321+00:00'
[2024-02-18T19:06:44.547+0000] {sql.py:276} INFO - Executing: <function load_data at 0x7f4948367ee0>
[2024-02-18T19:06:44.562+0000] {taskinstance.py:2698} ERROR - Task failed with exception
Traceback (most recent call last):
  File "/home/airflow/.local/lib/python3.8/site-packages/airflow/models/taskinstance.py", line 433, in _execute_task
    result = execute_callable(context=context, **execute_callable_kwargs)
  File "/home/airflow/.local/lib/python3.8/site-packages/airflow/providers/common/sql/operators/sql.py", line 277, in execute
    hook = self.get_db_hook()
  File "/home/airflow/.local/lib/python3.8/site-packages/airflow/providers/common/sql/operators/sql.py", line 188, in get_db_hook
    return self._hook
  File "/usr/local/lib/python3.8/functools.py", line 967, in __get__
    val = self.func(instance)
  File "/home/airflow/.local/lib/python3.8/site-packages/airflow/providers/common/sql/operators/sql.py", line 150, in _hook
    conn = BaseHook.get_connection(conn_id)
  File "/home/airflow/.local/lib/python3.8/site-packages/airflow/hooks/base.py", line 82, in get_connection
    conn = Connection.get_connection_from_secrets(conn_id)
  File "/home/airflow/.local/lib/python3.8/site-packages/airflow/models/connection.py", line 479, in get_connection_from_secrets
    raise AirflowNotFoundException(f"The conn_id `{conn_id}` isn't defined")
airflow.exceptions.AirflowNotFoundException: The conn_id `postgres_default` isn't defined
[2024-02-18T19:06:44.565+0000] {taskinstance.py:1138} INFO - Marking task as FAILED. dag_id=api_dag, task_id=load_data_task, execution_date=20240218T190639, start_date=20240218T190644, end_date=20240218T190644
[2024-02-18T19:06:44.575+0000] {standard_task_runner.py:107} ERROR - Failed to execute job 30 for task load_data_task (The conn_id `postgres_default` isn't defined; 3334)
[2024-02-18T19:06:44.608+0000] {local_task_job_runner.py:234} INFO - Task exited with return code 1
[2024-02-18T19:06:44.634+0000] {taskinstance.py:3280} INFO - 0 downstream tasks scheduled from follow-on schedule check
