[2024-02-18T22:10:58.728+0000] {taskinstance.py:1956} INFO - Dependencies all met for dep_context=non-requeueable deps ti=<TaskInstance: api_dag.transform_data_task manual__2024-02-18T22:10:56.163457+00:00 [queued]>
[2024-02-18T22:10:58.736+0000] {taskinstance.py:1956} INFO - Dependencies all met for dep_context=requeueable deps ti=<TaskInstance: api_dag.transform_data_task manual__2024-02-18T22:10:56.163457+00:00 [queued]>
[2024-02-18T22:10:58.737+0000] {taskinstance.py:2170} INFO - Starting attempt 1 of 1
[2024-02-18T22:10:58.746+0000] {taskinstance.py:2191} INFO - Executing <Task(PythonOperator): transform_data_task> on 2024-02-18 22:10:56.163457+00:00
[2024-02-18T22:10:58.750+0000] {standard_task_runner.py:60} INFO - Started process 402 to run task
[2024-02-18T22:10:58.752+0000] {standard_task_runner.py:87} INFO - Running: ['***', 'tasks', 'run', 'api_dag', 'transform_data_task', 'manual__2024-02-18T22:10:56.163457+00:00', '--job-id', '175', '--raw', '--subdir', 'DAGS_FOLDER/api_dag.py', '--cfg-path', '/tmp/tmpxl8_bz0g']
[2024-02-18T22:10:58.753+0000] {standard_task_runner.py:88} INFO - Job 175: Subtask transform_data_task
[2024-02-18T22:10:58.785+0000] {task_command.py:423} INFO - Running <TaskInstance: api_dag.transform_data_task manual__2024-02-18T22:10:56.163457+00:00 [running]> on host 4b96e3695163
[2024-02-18T22:10:58.836+0000] {taskinstance.py:2480} INFO - Exporting env vars: AIRFLOW_CTX_DAG_OWNER='***' AIRFLOW_CTX_DAG_ID='api_dag' AIRFLOW_CTX_TASK_ID='transform_data_task' AIRFLOW_CTX_EXECUTION_DATE='2024-02-18T22:10:56.163457+00:00' AIRFLOW_CTX_TRY_NUMBER='1' AIRFLOW_CTX_DAG_RUN_ID='manual__2024-02-18T22:10:56.163457+00:00'
[2024-02-18T22:11:02.360+0000] {taskinstance.py:2698} ERROR - Task failed with exception
Traceback (most recent call last):
  File "/home/airflow/.local/lib/python3.8/site-packages/sqlalchemy/engine/base.py", line 1910, in _execute_context
    self.dialect.do_execute(
  File "/home/airflow/.local/lib/python3.8/site-packages/sqlalchemy/engine/default.py", line 736, in do_execute
    cursor.execute(statement, parameters)
psycopg2.errors.UndefinedFunction: function hstore(text[], integer[]) does not exist
LINE 1: INSERT INTO automezzo (index, "0") VALUES (0, hstore(ARRAY['...
                                                      ^
HINT:  No function matches the given name and argument types. You might need to add explicit type casts.


The above exception was the direct cause of the following exception:

Traceback (most recent call last):
  File "/home/airflow/.local/lib/python3.8/site-packages/airflow/models/taskinstance.py", line 433, in _execute_task
    result = execute_callable(context=context, **execute_callable_kwargs)
  File "/home/airflow/.local/lib/python3.8/site-packages/airflow/operators/python.py", line 199, in execute
    return_value = self.execute_callable()
  File "/home/airflow/.local/lib/python3.8/site-packages/airflow/operators/python.py", line 216, in execute_callable
    return self.python_callable(*self.op_args, **self.op_kwargs)
  File "/opt/airflow/dags/api_dag.py", line 22, in transform_data
    df_data.to_sql('automezzo', conn, if_exists='replace')
  File "/home/airflow/.local/lib/python3.8/site-packages/pandas/core/generic.py", line 2878, in to_sql
    return sql.to_sql(
  File "/home/airflow/.local/lib/python3.8/site-packages/pandas/io/sql.py", line 769, in to_sql
    return pandas_sql.to_sql(
  File "/home/airflow/.local/lib/python3.8/site-packages/pandas/io/sql.py", line 1920, in to_sql
    total_inserted = sql_engine.insert_records(
  File "/home/airflow/.local/lib/python3.8/site-packages/pandas/io/sql.py", line 1470, in insert_records
    raise err
  File "/home/airflow/.local/lib/python3.8/site-packages/pandas/io/sql.py", line 1461, in insert_records
    return table.insert(chunksize=chunksize, method=method)
  File "/home/airflow/.local/lib/python3.8/site-packages/pandas/io/sql.py", line 1023, in insert
    num_inserted = exec_insert(conn, keys, chunk_iter)
  File "/home/airflow/.local/lib/python3.8/site-packages/pandas/io/sql.py", line 929, in _execute_insert
    result = conn.execute(self.table.insert(), data)
  File "/home/airflow/.local/lib/python3.8/site-packages/sqlalchemy/engine/base.py", line 1385, in execute
    return meth(self, multiparams, params, _EMPTY_EXECUTION_OPTS)
  File "/home/airflow/.local/lib/python3.8/site-packages/sqlalchemy/sql/elements.py", line 334, in _execute_on_connection
    return connection._execute_clauseelement(
  File "/home/airflow/.local/lib/python3.8/site-packages/sqlalchemy/engine/base.py", line 1577, in _execute_clauseelement
    ret = self._execute_context(
  File "/home/airflow/.local/lib/python3.8/site-packages/sqlalchemy/engine/base.py", line 1953, in _execute_context
    self._handle_dbapi_exception(
  File "/home/airflow/.local/lib/python3.8/site-packages/sqlalchemy/engine/base.py", line 2134, in _handle_dbapi_exception
    util.raise_(
  File "/home/airflow/.local/lib/python3.8/site-packages/sqlalchemy/util/compat.py", line 211, in raise_
    raise exception
  File "/home/airflow/.local/lib/python3.8/site-packages/sqlalchemy/engine/base.py", line 1910, in _execute_context
    self.dialect.do_execute(
  File "/home/airflow/.local/lib/python3.8/site-packages/sqlalchemy/engine/default.py", line 736, in do_execute
    cursor.execute(statement, parameters)
sqlalchemy.exc.ProgrammingError: (psycopg2.errors.UndefinedFunction) function hstore(text[], integer[]) does not exist
LINE 1: INSERT INTO automezzo (index, "0") VALUES (0, hstore(ARRAY['...
                                                      ^
HINT:  No function matches the given name and argument types. You might need to add explicit type casts.

[SQL: INSERT INTO automezzo (index, "0") VALUES (%(index)s, %(0)s)]
[parameters: {'index': 0, '0': {'id': 45499, 'telaio': '233015'}}]
(Background on this error at: https://sqlalche.me/e/14/f405)
[2024-02-18T22:11:02.373+0000] {taskinstance.py:1138} INFO - Marking task as FAILED. dag_id=api_dag, task_id=transform_data_task, execution_date=20240218T221056, start_date=20240218T221058, end_date=20240218T221102
[2024-02-18T22:11:02.382+0000] {standard_task_runner.py:107} ERROR - Failed to execute job 175 for task transform_data_task ((psycopg2.errors.UndefinedFunction) function hstore(text[], integer[]) does not exist
LINE 1: INSERT INTO automezzo (index, "0") VALUES (0, hstore(ARRAY['...
                                                      ^
HINT:  No function matches the given name and argument types. You might need to add explicit type casts.

[SQL: INSERT INTO automezzo (index, "0") VALUES (%(index)s, %(0)s)]
[parameters: {'index': 0, '0': {'id': 45499, 'telaio': '233015'}}]
(Background on this error at: https://sqlalche.me/e/14/f405); 402)
[2024-02-18T22:11:02.426+0000] {local_task_job_runner.py:234} INFO - Task exited with return code 1
[2024-02-18T22:11:02.440+0000] {taskinstance.py:3280} INFO - 0 downstream tasks scheduled from follow-on schedule check
