[2024-02-22T18:32:54.016+0000] {taskinstance.py:1956} INFO - Dependencies all met for dep_context=non-requeueable deps ti=<TaskInstance: api_dag.extract_csv_data manual__2024-02-22T18:32:49.708660+00:00 [queued]>
[2024-02-22T18:32:54.031+0000] {taskinstance.py:1956} INFO - Dependencies all met for dep_context=requeueable deps ti=<TaskInstance: api_dag.extract_csv_data manual__2024-02-22T18:32:49.708660+00:00 [queued]>
[2024-02-22T18:32:54.031+0000] {taskinstance.py:2170} INFO - Starting attempt 1 of 1
[2024-02-22T18:32:54.049+0000] {taskinstance.py:2191} INFO - Executing <Task(PythonOperator): extract_csv_data> on 2024-02-22 18:32:49.708660+00:00
[2024-02-22T18:32:54.056+0000] {standard_task_runner.py:60} INFO - Started process 1070 to run task
[2024-02-22T18:32:54.062+0000] {standard_task_runner.py:87} INFO - Running: ['***', 'tasks', 'run', 'api_dag', 'extract_csv_data', 'manual__2024-02-22T18:32:49.708660+00:00', '--job-id', '237', '--raw', '--subdir', 'DAGS_FOLDER/api_dag.py', '--cfg-path', '/tmp/tmpb3sjn60q']
[2024-02-22T18:32:54.063+0000] {standard_task_runner.py:88} INFO - Job 237: Subtask extract_csv_data
[2024-02-22T18:32:54.120+0000] {task_command.py:423} INFO - Running <TaskInstance: api_dag.extract_csv_data manual__2024-02-22T18:32:49.708660+00:00 [running]> on host 614a08523528
[2024-02-22T18:32:54.205+0000] {taskinstance.py:2480} INFO - Exporting env vars: AIRFLOW_CTX_DAG_OWNER='***' AIRFLOW_CTX_DAG_ID='api_dag' AIRFLOW_CTX_TASK_ID='extract_csv_data' AIRFLOW_CTX_EXECUTION_DATE='2024-02-22T18:32:49.708660+00:00' AIRFLOW_CTX_TRY_NUMBER='1' AIRFLOW_CTX_DAG_RUN_ID='manual__2024-02-22T18:32:49.708660+00:00'
[2024-02-22T18:32:54.208+0000] {taskinstance.py:2698} ERROR - Task failed with exception
Traceback (most recent call last):
  File "/home/airflow/.local/lib/python3.8/site-packages/airflow/models/taskinstance.py", line 433, in _execute_task
    result = execute_callable(context=context, **execute_callable_kwargs)
  File "/home/airflow/.local/lib/python3.8/site-packages/airflow/operators/python.py", line 199, in execute
    return_value = self.execute_callable()
  File "/home/airflow/.local/lib/python3.8/site-packages/airflow/operators/python.py", line 216, in execute_callable
    return self.python_callable(*self.op_args, **self.op_kwargs)
  File "/opt/airflow/dags/api_dag.py", line 16, in extract_csv_data
    csv_data = pd.read_csv(csv_path_file)
  File "/home/airflow/.local/lib/python3.8/site-packages/pandas/io/parsers/readers.py", line 912, in read_csv
    return _read(filepath_or_buffer, kwds)
  File "/home/airflow/.local/lib/python3.8/site-packages/pandas/io/parsers/readers.py", line 577, in _read
    parser = TextFileReader(filepath_or_buffer, **kwds)
  File "/home/airflow/.local/lib/python3.8/site-packages/pandas/io/parsers/readers.py", line 1407, in __init__
    self._engine = self._make_engine(f, self.engine)
  File "/home/airflow/.local/lib/python3.8/site-packages/pandas/io/parsers/readers.py", line 1661, in _make_engine
    self.handles = get_handle(
  File "/home/airflow/.local/lib/python3.8/site-packages/pandas/io/common.py", line 859, in get_handle
    handle = open(
FileNotFoundError: [Errno 2] No such file or directory: '\\wsl.localhost\\Ubuntu\\home\\angelica_linux\\project2\\airflow-docker\\files\\record_italia.csv'
[2024-02-22T18:32:54.217+0000] {taskinstance.py:1138} INFO - Marking task as FAILED. dag_id=api_dag, task_id=extract_csv_data, execution_date=20240222T183249, start_date=20240222T183254, end_date=20240222T183254
[2024-02-22T18:32:54.229+0000] {standard_task_runner.py:107} ERROR - Failed to execute job 237 for task extract_csv_data ([Errno 2] No such file or directory: '\\wsl.localhost\\Ubuntu\\home\\angelica_linux\\project2\\airflow-docker\\files\\record_italia.csv'; 1070)
[2024-02-22T18:32:54.235+0000] {local_task_job_runner.py:234} INFO - Task exited with return code 1
[2024-02-22T18:32:54.256+0000] {taskinstance.py:3280} INFO - 0 downstream tasks scheduled from follow-on schedule check
