[2024-02-24T17:18:55.893+0000] {taskinstance.py:1956} INFO - Dependencies all met for dep_context=non-requeueable deps ti=<TaskInstance: api_dag.transform_data_task manual__2024-02-24T17:18:51.474407+00:00 [queued]>
[2024-02-24T17:18:55.899+0000] {taskinstance.py:1956} INFO - Dependencies all met for dep_context=requeueable deps ti=<TaskInstance: api_dag.transform_data_task manual__2024-02-24T17:18:51.474407+00:00 [queued]>
[2024-02-24T17:18:55.899+0000] {taskinstance.py:2170} INFO - Starting attempt 1 of 1
[2024-02-24T17:18:55.906+0000] {taskinstance.py:2191} INFO - Executing <Task(PythonOperator): transform_data_task> on 2024-02-24 17:18:51.474407+00:00
[2024-02-24T17:18:55.910+0000] {standard_task_runner.py:60} INFO - Started process 3804 to run task
[2024-02-24T17:18:55.913+0000] {standard_task_runner.py:87} INFO - Running: ['***', 'tasks', 'run', 'api_dag', 'transform_data_task', 'manual__2024-02-24T17:18:51.474407+00:00', '--job-id', '816', '--raw', '--subdir', 'DAGS_FOLDER/api_dag.py', '--cfg-path', '/tmp/tmphhqpe8lc']
[2024-02-24T17:18:55.914+0000] {standard_task_runner.py:88} INFO - Job 816: Subtask transform_data_task
[2024-02-24T17:18:55.977+0000] {task_command.py:423} INFO - Running <TaskInstance: api_dag.transform_data_task manual__2024-02-24T17:18:51.474407+00:00 [running]> on host 614a08523528
[2024-02-24T17:18:56.049+0000] {taskinstance.py:2480} INFO - Exporting env vars: AIRFLOW_CTX_DAG_OWNER='***' AIRFLOW_CTX_DAG_ID='api_dag' AIRFLOW_CTX_TASK_ID='transform_data_task' AIRFLOW_CTX_EXECUTION_DATE='2024-02-24T17:18:51.474407+00:00' AIRFLOW_CTX_TRY_NUMBER='1' AIRFLOW_CTX_DAG_RUN_ID='manual__2024-02-24T17:18:51.474407+00:00'
[2024-02-24T17:18:56.130+0000] {taskinstance.py:2698} ERROR - Task failed with exception
Traceback (most recent call last):
  File "/home/airflow/.local/lib/python3.8/site-packages/airflow/models/taskinstance.py", line 433, in _execute_task
    result = execute_callable(context=context, **execute_callable_kwargs)
  File "/home/airflow/.local/lib/python3.8/site-packages/airflow/operators/python.py", line 199, in execute
    return_value = self.execute_callable()
  File "/home/airflow/.local/lib/python3.8/site-packages/airflow/operators/python.py", line 216, in execute_callable
    return self.python_callable(*self.op_args, **self.op_kwargs)
  File "/opt/airflow/dags/api_dag.py", line 40, in transform_data
    selected_csv2 = df_csv2.loc[:, ['Targa', 'km']].rename(columns={'Targa': 'Mezzo', 'Km (CAN)': 'Km Totali (Km)'})
  File "/home/airflow/.local/lib/python3.8/site-packages/pandas/core/indexing.py", line 1097, in __getitem__
    return self._getitem_tuple(key)
  File "/home/airflow/.local/lib/python3.8/site-packages/pandas/core/indexing.py", line 1289, in _getitem_tuple
    return self._getitem_tuple_same_dim(tup)
  File "/home/airflow/.local/lib/python3.8/site-packages/pandas/core/indexing.py", line 955, in _getitem_tuple_same_dim
    retval = getattr(retval, self.name)._getitem_axis(key, axis=i)
  File "/home/airflow/.local/lib/python3.8/site-packages/pandas/core/indexing.py", line 1332, in _getitem_axis
    return self._getitem_iterable(key, axis=axis)
  File "/home/airflow/.local/lib/python3.8/site-packages/pandas/core/indexing.py", line 1272, in _getitem_iterable
    keyarr, indexer = self._get_listlike_indexer(key, axis)
  File "/home/airflow/.local/lib/python3.8/site-packages/pandas/core/indexing.py", line 1462, in _get_listlike_indexer
    keyarr, indexer = ax._get_indexer_strict(key, axis_name)
  File "/home/airflow/.local/lib/python3.8/site-packages/pandas/core/indexes/base.py", line 5877, in _get_indexer_strict
    self._raise_if_missing(keyarr, indexer, axis_name)
  File "/home/airflow/.local/lib/python3.8/site-packages/pandas/core/indexes/base.py", line 5941, in _raise_if_missing
    raise KeyError(f"{not_found} not in index")
KeyError: "['km'] not in index"
[2024-02-24T17:18:56.139+0000] {taskinstance.py:1138} INFO - Marking task as FAILED. dag_id=api_dag, task_id=transform_data_task, execution_date=20240224T171851, start_date=20240224T171855, end_date=20240224T171856
[2024-02-24T17:18:56.150+0000] {standard_task_runner.py:107} ERROR - Failed to execute job 816 for task transform_data_task ("['km'] not in index"; 3804)
[2024-02-24T17:18:56.166+0000] {local_task_job_runner.py:234} INFO - Task exited with return code 1
[2024-02-24T17:18:56.179+0000] {taskinstance.py:3280} INFO - 0 downstream tasks scheduled from follow-on schedule check
